File: example_data.dat
[Header]
; MPMS3 Data File (default extension .dat)
; Copyright (c) 2007, Quantum Design, Inc. All rights reserved.
TITLE,
FILEOPENTIME,3765441026.01351,04/26/2019,12:49 pm
BYAPP,SQUID AC,0.9.1.0
INFO,MPMS3 Measurement Release 1.1.16 Build 347, MultiVu Release 2.3.3.2,APPNAME
INFO,0,MOMENT_UNITS
INFO,Sp11Cu,SAMPLE_MATERIAL
INFO,,SAMPLE_COMMENT
INFO,,SAMPLE_MASS
INFO,,SAMPLE_VOLUME
INFO,,SAMPLE_MOLECULAR_WEIGHT
INFO,,SAMPLE_SIZE
INFO,,SAMPLE_SHAPE
INFO,Brass,SAMPLE_HOLDER
INFO,Standard,SAMPLE_HOLDER_DETAIL
INFO,66.29,SAMPLE_OFFSET
DATATYPE,COMMENT,1
DATATYPE,TIME,2
STARTUPAXIS,X,2
STARTUPAXIS,Y1,5
FIELDGROUP, VSM,2,3,4,5,6,8,9,10,11,14,15
FIELDGROUP, DC, 2,3,4,14,56,57,58,59,60,61,62,63,64,65,66,67,68,69
FIELDGROUP, AC, 2,3,4,11,16,17,18,19,20,21,22,23,24,25,26,27,28,29,30
STARTUPGROUP, All
[Data]
Comment,Time Stamp (sec),Temperature (K),Magnetic Field (Oe),Moment (emu),M. Std. Err. (emu),Transport Action,Averaging Time (sec),Frequency (Hz),Peak Amplitude (mm),Center Position (mm),Lockin Signal' (V),Lockin Signal (V),Range,M. Quad. Signal (emu),AC Moment (emu),AC M. Std Err. (emu),AC Phase (deg),AC Phase Std. Err. (deg),AC Susceptibility (emu/Oe),AC Suscept. Std Err. (emu/Oe),AC X' (emu/Oe),AC X' Std Err. (emu/Oe),AC X'' (emu/Oe),AC X'' Std Err. (emu/Oe),AC Drive (Oe),AC Frequency (Hz),AC Averaging Time (sec),AC Cycles,AC Range,AC Measure Type,AC Signal' (V),AC Signal'' (V),AC Trim Coil Ratio,AC Trim Coil Phase,Min. Temperature (K),Max. Temperature (K),Min. Field (Oe),Max. Field (Oe),Mass (grams),Motor Lag (deg),Pressure (Torr),Measure Count,Measurement Number,SQUID Status (code),Motor Status (code),Measure Status (code),Motor Current (amps),Motor Temp. (C),Temp. Status (code),Field Status (code),Chamber Status (code),Chamber Temp (K),Redirection State,Average Temp (K),Rotation Angle (deg),Rotator state,DC Moment Fixed Ctr (emu),DC Moment Err Fixed Ctr (emu),DC Moment Free Ctr (emu),DC Moment Err Free Ctr (emu),DC Fixed Fit,DC Free Fit,DC Calculated Center (mm),DC Calculated Center Err (mm),DC Scan Length (mm),DC Scan Time (s),DC Number of Points,DC Squid Drift,DC Min V (V),DC Max V (V),DC Scans per Measure,Map 01,Map 02,Map 03,Map 04,Map 05,Map 06,Map 07,Map 08,Map 09,Map 10,Map 11,Map 12,Map 13,Map 14,Map 15,Map 16
,3765441055.23659,299.876098632812,399.644134521484,0.000608512200277114,7.14140500411623E-8,1,2,13.9012460708618,4.9984942451517,4.91000013425946,0.730164766186024,0.108926105348669,10,-2.58305886644431E-6,,,,,,,,,,,,,,,,,,,,,299.876098632812,299.876098632812,399.644134521484,399.644134521484,52.7376486352844,5.67499974857391,31.3964233398438,28,1,0,0,1,0.309371948242188,31.2805480957031,1,1,1,299.876098632812,0,299.876098632812,,,,,,,,,,,,,,,,,,,,,,,,,,,,,,,,,
,3765441079.21738,299.897384643555,380.252075195313,0.000608430545697872,5.40635027089939E-8,1,2,13.9012460708618,4.99860001775219,4.91000013425946,0.729886667662794,0.110229908481182,1,-1.48598144406677E-6,,,,,,,,,,,,,,,,,,,,,299.894622802734,299.900146484375,380.252075195313,380.252075195313,52.659876597621,5.67454284712125,31.4337348937988,28,1,0,0,1,0.30792236328125,31.7693061828613,1,1,1,299.900146484375,0,299.897384643555,,,,,,,,,,,,,,,,,,,,,,,,,,,,,,,,,
,3765441100.3575,299.974761962891,360.179992675781,0.000608623553706652,4.96988611941236E-8,1,2,13.9012460708618,4.99852663215076,4.91000013425946,0.730132368989701,0.110071858785193,1,-1.64551088375854E-6,,,,,,,,,,,,,,,,,,,,,299.964935302734,299.984588623047,360.179992675781,360.179992675781,52.7255333932363,5.67475585235502,31.4959182739258,28,1,0,0,1,0.31005859375,31.7693061828613,1,1,1,299.984588623047,0,299.974761962891,,,,,,,,,,,,,,,,,,,,,,,,,,,,,,,,,
,3765441119.99868,300.149993896484,340.107940673828,0.000608651517576396,4.88135005982759E-8,1,2,13.9012460708618,4.99842132551377,4.91000013425946,0.730152024050544,0.110022816969596,1,-1.68797497432284E-6,,,,,,,,,,,,,,,,,,,,,300.148986816406,300.151000976562,340.107940673828,340.107940673828,52.7403843351017,5.67487957677342,31.55810546875,28,1,0,0,1,0.308761596679687,31.7693061828613,1,1,1,300.148986816406,0,300.149993896484,,,,,,,,,,,,,,,,,,,,,,,,,,,,,,,,,
,3765441140.34654,300.127944946289,320.120880126953,0.000608843326881878,6.46751116288486E-8,1,2,13.9012460708618,4.99838535180429,4.91000013425946,0.730368964512728,0.110093791006301,1,-1.65730119296642E-6,,,,,,,,,,,,,,,,,,,,,300.127471923828,300.12841796875,320.120880126953,320.120880126953,52.6270481998133,5.6751519391488,31.6327285766602,28,1,0,0,1,0.309219360351562,32.2580642700195,1,1,1,300.127471923828,0,300.127944946289,,,,,,,,,,,,,,,,,,,,,,,,,,,,,,,,,
,3765441161.60297,300.076629638672,300.218811035156,0.000608978510596825,5.58753837642688E-8,1,2,13.9012460708618,4.99835924251847,4.91000013425946,0.730532210472988,0.110075336666428,1,-1.69276877001897E-6,,,,,,,,,,,,,,,,,,,,,300.069091796875,300.084167480469,300.218811035156,300.218811035156,52.5852310740344,5.67518030782199,31.7322235107422,28,1,0,0,1,0.309371948242188,32.2580642700195,1,1,1,300.069091796875,0,300.076629638672,,,,,,,,,,,,,,,,,,,,,,,,,,,,,,,,,
,3765441182.15286,300.020141601562,280.134613037109,0.0006090780352158,6.32831145726409E-8,1,2,13.9012460708618,4.99824226208666,4.91000013425946,0.73059683924214,0.11028929605539,1,-1.52657722562511E-6,,,,,,,,,,,,,,,,,,,,,300.018798828125,300.021484375,280.134613037109,280.134613037109,52.7415567778806,5.67539458935772,31.8068466186523,28,1,0,0,1,0.309219360351562,32.2580642700195,1,1,1,300.021484375,0,300.020141601562,,,,,,,,,,,,,,,,,,,,,,,,,,,,,,,,,
,3765441204.97545,300.064010620117,260.183959960938,0.000609197149571818,6.13088728781719E-8,1,2,13.9012460708618,4.99828752237235,4.91000013425946,0.730752179040795,0.110291899110399,1,-1.54386774796369E-6,,,,,,,,,,,,,,,,,,,,,300.054046630859,300.073974609375,260.183959960938,260.183959960938,52.6551868265056,5.67503267750424,31.9187812805176,28,1,0,0,1,0.310592651367188,32.2580642700195,1,1,1,300.073974609375,0,300.064010620117,,,,,,,,,,,,,,,,,,,,,,,,,,,,,,,,,
,3765441225.61763,300.259307861328,240.245483398438,0.000609246401848162,2.91118530033283E-8,1,2,13.9012460708618,4.9981688207302,4.91000013425946,0.730794305957306,0.110248101581784,1,-1.5848756285261E-6,,,,,,,,,,,,,,,,,,,,,300.249206542969,300.269409179687,240.245483398438,240.245483398438,52.7442924776979,5.6754906148878,31.9685287475586,28,1,0,0,1,0.308914184570313,32.2580642700195,1,1,1,300.269409179687,0,300.259307861328,,,,,,,,,,,,,,,,,,,,,,,,,,,,,,,,,
,3765441250.43861,300.36540222168,220.185562133789,0.000609250591814193,5.44236061706254E-8,1,2,13.9012460708618,4.9981488534114,4.91000013425946,0.730800002315375,0.110217049622696,1,-1.61089858102735E-6,,,,,,,,,,,,,,,,,,,,,300.363067626953,300.367736816406,220.185562133789,220.185562133789,52.5828861884767,5.67534307644054,32.0928993225098,28,1,0,0,1,0.309219360351562,32.7468223571777,1,1,1,300.363067626953,0,300.36540222168,,,,,,,,,,,,,,,,,,,,,,,,,,,,,,,,,
,3765441271.12448,300.309814453125,200.149917602539,0.000609300224455284,7.12630175891278E-8,1,2,13.9012460708618,4.99817221030767,4.91000013425946,0.730863082095649,0.11023504076858,1,-1.60411938294092E-6,,,,,,,,,,,,,,,,,,,,,300.309600830078,300.310028076172,200.149917602539,200.149917602539,52.6168870290633,5.67472081295916,32.1799621582031,28,1,0,0,1,0.3082275390625,32.2580642700195,1,1,1,300.310028076172,0,300.309814453125,,,,,,,,,,,,,,,,,,,,,,,,,,,,,,,,,
,3765441296.60038,300.309097290039,180.053573608398,0.000609315404789049,7.27102714341001E-8,1,2,13.9012460708618,4.99811524665141,4.91000013425946,0.730873949557858,0.110207309049606,1,-1.6281009138091E-6,,,,,,,,,,,,,,,,,,,,,300.30322265625,300.314971923828,180.053573608398,180.053573608398,52.6571408978036,5.67483822830268,32.2794570922852,28,1,0,0,1,0.308151245117188,32.7468223571777,1,1,1,300.30322265625,0,300.309097290039,,,,,,,,,,,,,,,,,,,,,,,,,,,,,,,,,
,3765441317.08389,300.130981445313,160.248657226562,0.000609365873707464,4.83665657254434E-8,1,2,13.9012460708618,4.99757866028618,4.91000013425946,0.730817624716553,0.110240002089341,1,-1.59465768081718E-6,,,,,,,,,,,,,,,,,,,,,300.124450683594,300.137512207031,160.248657226562,160.248657226562,52.6911417383902,5.67800034468778,32.3665161132812,28,1,0,0,1,0.30914306640625,32.2580642700195,1,1,1,300.124450683594,0,300.130981445313,,,,,,,,,,,,,,,,,,,,,,,,,,,,,,,,,
,3765441337.74972,299.997924804687,140.17658996582,0.000609293363964887,5.88952605856713E-8,1,2,13.9012460708618,4.99797490653431,4.91000013425946,0.730811071231118,0.110247786479621,1,-1.58731641682521E-6,,,,,,,,,,,,,,,,,,,,,299.989715576172,300.006134033203,140.17658996582,140.17658996582,52.6696469541113,5.67556390649939,32.4287033081055,28,1,0,0,1,0.309219360351562,32.2580642700195,1,1,1,299.989715576172,0,299.997924804687,,,,,,,,,,,,,,,,,,,,,,,,,,,,,,,,,
,3765441358.38121,299.929840087891,120.104522705078,0.000609198415698384,3.46664527461099E-8,1,2,13.9012460708618,4.99798647427781,4.91000013425946,0.730699050154872,0.110234364056659,1,-1.58423493538256E-6,,,,,,,,,,,,,,,,,,,,,299.926544189453,299.933135986328,120.104522705078,120.104522705078,52.6841070817171,5.6754058421007,32.5281982421875,28,1,0,0,1,0.30914306640625,32.2580642700195,1,1,1,299.933135986328,0,299.929840087891,,,,,,,,,,,,,,,,,,,,,,,,,,,,,,,,,
,3765441378.9596,299.947006225586,100.081031799316,0.000609034795285475,4.86618148553627E-8,1,2,13.9012460708618,4.99798111628457,4.91000013425946,0.730484618815592,0.110315801131358,1,-1.49105360923136E-6,,,,,,,,,,,,,,,,,,,,,299.942993164063,299.951019287109,100.081031799316,100.081031799316,52.7439016634383,5.67517470504917,32.6152610778809,28,1,0,0,1,0.309982299804687,32.7468223571777,1,1,1,299.942993164063,0,299.947006225586,,,,,,,,,,,,,,,,,,,,,,,,,,,,,,,,,
,3765441399.6238,299.92854309082,80.1668243408203,0.00060883633714724,2.71421345759778E-8,1,2,13.9012460708618,4.99795444998038,4.91000013425946,0.73025524435886,0.110186826424067,1,-1.56746614168489E-6,,,,,,,,,,,,,,,,,,,,,299.927856445313,299.929229736328,80.1668243408203,80.1668243408203,52.6989580235825,5.67519409741241,32.702320098877,28,1,0,0,1,0.309829711914063,32.7468223571777,1,1,1,299.927856445313,0,299.92854309082,,,,,,,,,,,,,,,,,,,,,,,,,,,,,,,,,
,3765441422.144,299.80729675293,60.1554756164551,0.000608494309869688,4.33880649243088E-8,1,2,13.9012460708618,4.99780990490813,4.91000013425946,0.729807543148925,0.11017053687887,1,-1.52479526019905E-6,,,,,,,,,,,,,,,,,,,,,299.795227050781,299.819366455078,60.1554756164551,60.1554756164551,52.7833739036594,5.67620854484251,32.7769432067871,28,1,0,0,1,0.309906005859375,32.2580642700195,1,1,1,299.795227050781,0,299.80729675293,,,,,,,,,,,,,,,,,,,,,,,,,,,,,,,,,
,3765441446.06252,299.739715576172,40.0834121704102,0.000607962919195378,7.2232486683869E-8,1,2,13.9012460708618,4.99778203380185,4.91000013425946,0.729175245515061,0.110003307306833,1,-1.58197847608607E-6,,,,,,,,,,,,,,,,,,,,,299.734100341797,299.745330810547,40.0834121704102,40.0834121704102,52.6035993442363,5.67658639470267,32.9013137817383,28,1,0,0,1,0.3094482421875,32.7468223571777,1,1,1,299.734100341797,0,299.739715576172,,,,,,,,,,,,,,,,,,,,,,,,,,,,,,,,,
,3765441482.68781,299.563537597656,20.0720634460449,0.000607178821869427,1.99850097443654E-8,1,2,13.9012460708618,4.99771415689729,4.91000013425946,0.728200793947023,0.109990088927833,1,-1.47086998841008E-6,,,,,,,,,,,,,,,,,,,,,299.560913085937,299.566162109375,20.0720634460449,20.0720634460449,52.6204043573998,5.67666099823404,33.0132484436035,28,1,0,0,1,0.30853271484375,32.7468223571777,1,1,1,299.566467285156,0,299.563537597656,,,,,,,,,,,,,,,,,,,,,,,,,,,,,,,,,
,3765441507.00118,299.615966796875,0.145713716745377,0.000605759144204584,3.9591681709481E-8,1,2,13.9012460708618,4.99757224233918,4.91000013425946,0.726473048081909,0.109702471799359,1,-1.48915890729134E-6,,,,,,,,,,,,,,,,,,,,,299.608734130859,299.623199462891,0.145713716745377,0.145713716745377,52.6641755544767,5.67748128975211,33.1127433776855,28,1,0,0,1,0.310592651367188,32.7468223571777,1,1,1,299.623199462891,0,299.615966796875,,,,,,,,,,,,,,,,,,,,,,,,,,,,,,,,,
,3765441526.99988,299.731552124023,-20.0599212646484,0.000595660328901591,3.93092893470844E-8,1,2,13.9012460708618,4.99751502794843,4.91000013425946,0.714379036437524,0.107684233788077,1,-1.62082927869786E-6,,,,,,,,,,,,,,,,,,,,,299.719665527344,299.743438720703,-20.0599212646484,-20.0599212646484,52.6790264963421,5.67817760513888,33.1873664855957,28,1,0,0,1,0.3106689453125,32.7468223571777,1,1,1,299.744323730469,0,299.731552124023,,,,,,,,,,,,,,,,,,,,,,,,,,,,,,,,,
,3765441547.949,299.975067138672,-39.9741287231445,-0.000537228241520371,7.30119978935049E-8,1,2,13.9012460708618,4.99736478762635,4.91000013425946,-0.64427171235872,-0.0971300097125404,1,1.45071885141075E-6,,,,,,,,,,,,,,,,,,,,,299.968170166016,299.981964111328,-39.9741287231445,-39.9741287231445,52.6372093705633,5.67919804014308,33.2619895935059,28,1,0,0,1,0.311203002929687,32.7468223571777,1,1,1,299.981964111328,0,299.975067138672,,,,,,,,,,,,,,,,,,,,,,,,,,,,,,,,,
,3765441570.55112,299.885192871094,-59.9490509033203,-0.000589693391750831,6.68272530104457E-8,1,2,13.9012460708618,4.99734682637965,4.91000013425946,-0.707190105335032,-0.106595058855939,1,1.60910016970648E-6,,,,,,,,,,,,,,,,,,,,,299.863067626953,299.907318115234,-59.9490509033203,-59.9490509033203,52.6610490403998,5.67845313408753,33.386360168457,28,1,0,0,1,0.31097412109375,32.7468223571777,1,1,1,299.863067626953,0,299.885192871094,,,,,,,,,,,,,,,,,,,,,,,,,,,,,,,,,
,3765441591.66197,299.892227172852,-79.9846878051758,-0.000594739681603917,6.66912433054301E-8,1,2,13.9012460708618,4.997116426999,4.91000013425946,-0.713147439213689,-0.10781319951211,1,1.36179115983636E-6,,,,,,,,,,,,,,,,,,,,,299.886596679687,299.897857666016,-79.9846878051758,-79.9846878051758,52.6813713818998,5.67923707706563,33.448543548584,28,1,0,0,1,0.310821533203125,32.7468223571777,1,1,1,299.897857666016,0,299.892227172852,,,,,,,,,,,,,,,,,,,,,,,,,,,,,,,,,
,3765441612.46721,299.962951660156,-100.03246307373,-0.000597361723410764,5.84390037259494E-8,1,2,13.9012460708618,4.99706506361163,4.91000013425946,-0.716301454406716,-0.108154505652818,1,1.47828733907767E-6,,,,,,,,,,,,,,,,,,,,,299.961456298828,299.964447021484,-100.03246307373,-100.03246307373,52.7052110517363,5.67977914549105,33.448543548584,28,1,0,0,1,0.310287475585937,32.7468223571777,1,1,1,299.964447021484,0,299.962951660156,,,,,,,,,,,,,,,,,,,,,,,,,,,,,,,,,
,3765441635.00924,299.927429199219,-119.946670532227,-0.000599745843769922,6.97648756757396E-8,1,2,13.9012460708618,4.99715831261996,4.91000013425946,-0.719198106583704,-0.108465897901282,1,1.58689982020869E-6,,,,,,,,,,,,,,,,,,,,,299.923034667969,299.931823730469,-119.946670532227,-119.946670532227,52.6442440272363,5.67970165467878,33.4112358093262,28,1,0,0,1,0.310134887695313,32.7468223571777,1,1,1,299.923034667969,0,299.927429199219,,,,,,,,,,,,,,,,,,,,,,,,,,,,,,,,,
,3765441660.68625,299.830383300781,-139.994445800781,-0.00060161970277789,7.82086006032975E-8,1,2,13.9012460708618,4.99718917770827,4.91000013425946,-0.721454686878909,-0.108784791274361,1,1.6093335355114E-6,,,,,,,,,,,,,,,,,,,,,299.829742431641,299.831024169922,-139.994445800781,-139.994445800781,52.6981763950633,5.6790614105518,33.4236717224121,28,1,0,0,1,0.311126708984375,32.7468223571777,1,1,1,299.831024169922,0,299.830383300781,,,,,,,,,,,,,,,,,,,,,,,,,,,,,,,,,
,3765441686.35663,299.838287353516,-160.139373779297,-0.000603065534805888,6.46490641935773E-8,1,2,13.9012460708618,4.99732316425467,4.91000013425946,-0.723207247912466,-0.10910647203122,1,1.56638440958278E-6,,,,,,,,,,,,,,,,,,,,,299.826599121094,299.849975585937,-160.139373779297,-160.139373779297,52.6786356820825,5.6786531719559,33.4982948303223,28,1,0,0,1,0.31005859375,32.7468223571777,1,1,1,299.826599121094,0,299.838287353516,,,,,,,,,,,,,,,,,,,,,,,,,,,,,,,,,
,3765441710.29475,299.836975097656,-179.96858215332,-0.000604225479851163,4.70835515398212E-8,1,2,13.9012460708618,4.99710697312276,4.91000013425946,-0.724551418722604,-0.109326830014543,1,1.55507107325469E-6,,,,,,,,,,,,,,,,,,,,,299.829315185547,299.844635009766,-179.96858215332,-179.96858215332,52.529735449169,5.67936254995112,33.5729179382324,28,1,0,0,1,0.309829711914063,32.7468223571777,1,1,1,299.829315185547,0,299.836975097656,,,,,,,,,,,,,,,,,,,,,,,,,,,,,,,,,
,3765441734.44092,299.791213989258,-200.004211425781,-0.000605166987602648,6.38673426445734E-8,1,2,13.9012460708618,4.99693220947069,4.91000013425946,-0.725651740384866,-0.109445376708084,1,1.59620974467065E-6,,,,,,,,,,,,,,,,,,,,,299.78369140625,299.798736572266,-200.004211425781,-200.004211425781,52.7560169054864,5.67976547335484,33.6599769592285,28,1,0,0,1,0.311126708984375,32.7468223571777,1,1,1,299.78369140625,0,299.791213989258,,,,,,,,,,,,,,,,,,,,,,,,,,,,,,,,,
,3765441755.37587,299.772232055664,-220.039855957031,-0.00060584328042321,7.99919576350558E-8,1,2,13.9012460708618,4.99680213047316,4.91000013425946,-0.726403287038161,-0.109776741877772,1,1.42021381731007E-6,,,,,,,,,,,,,,,,,,,,,299.770904541016,299.773559570313,-220.039855957031,-220.039855957031,52.8216737011017,5.68001649863544,33.7470321655273,28,1,0,0,1,0.309600830078125,32.7468223571777,1,1,1,299.773864746094,0,299.772232055664,,,,,,,,,,,,,,,,,,,,,,,,,,,,,,,,,
,3765441777.99697,299.841247558594,-239.954040527344,-0.000606375256022108,4.43438423403311E-8,1,2,13.9012460708618,4.99691303495796,4.91000013425946,-0.727087562685956,-0.109722368482184,1,1.550115755572E-6,,,,,,,,,,,,,,,,,,,,,299.840789794922,299.841705322266,-239.954040527344,-239.954040527344,52.773603547169,5.67976467501152,33.8340950012207,28,1,0,0,1,0.31097412109375,32.7468223571777,1,1,1,299.840789794922,0,299.841247558594,,,,,,,,,,,,,,,,,,,,,,,,,,,,,,,,,
,3765441803.59588,299.785491943359,-259.916839599609,-0.000606865195808316,6.82590628714934E-8,1,2,13.9012460708618,4.99683765231984,4.91000013425946,-0.72767483166667,-0.109709138114309,1,1.63442254298663E-6,,,,,,,,,,,,,,,,,,,,,299.773101806641,299.797882080078,-259.916839599609,-259.916839599609,52.6235308714767,5.68068650653878,33.9460258483887,28,1,0,0,1,0.312347412109375,32.7468223571777,1,1,1,299.773101806641,0,299.785491943359,,,,,,,,,,,,,,,,,,,,,,,,,,,,,,,,,
,3765441829.16794,299.679840087891,-279.928192138672,-0.000607179452130089,5.56475272704843E-8,1,2,13.9012460708618,4.9967438933949,4.91000013425946,-0.728031235436467,-0.109770466222896,1,1.62907598859099E-6,,,,,,,,,,,,,,,,,,,,,299.674377441406,299.685302734375,-279.928192138672,-279.928192138672,52.690360109871,5.6810918804625,34.0206489562988,28,1,0,0,1,0.310897827148438,32.7468223571777,1,1,1,299.674377441406,0,299.679840087891,,,,,,,,,,,,,,,,,,,,,,,,,,,,,,,,,
,3765441852.22524,299.684448242188,-299.95166015625,-0.000607440896246524,7.10092803872282E-8,1,2,13.9012460708618,4.99676821125117,4.91000013425946,-0.728350231746977,-0.109815137505271,1,1.63257128327629E-6,,,,,,,,,,,,,,,,,,,,,299.680633544922,299.688262939453,-299.95166015625,-299.95166015625,52.753281205669,5.6808017706376,34.082836151123,28,1,0,0,1,0.310745239257812,32.7468223571777,1,1,1,299.680633544922,0,299.684448242188,,,,,,,,,,,,,,,,,,,,,,,,,,,,,,,,,
,3765441877.86869,299.620346069336,-319.999450683594,-0.000607568432416155,4.41024614230719E-8,1,2,13.9012460708618,4.99675203370324,4.91000013425946,-0.728491499337471,-0.109891930459825,1,1.58766072114639E-6,,,,,,,,,,,,,,,,,,,,,299.613555908203,299.627136230469,-319.999450683594,-319.999450683594,52.7556260912267,5.6807597818058,34.1947708129883,28,1,0,0,1,0.310745239257812,32.7468223571777,1,1,1,299.613555908203,0,299.620346069336,,,,,,,,,,,,,,,,,,,,,,,,,,,,,,,,,
,3765441914.82927,299.584747314453,-339.986511230469,-0.000607751826453941,4.03560437971785E-8,1,2,13.9012460708618,4.99669221348302,4.91000013425946,-0.728703222592725,-0.109896300537771,1,1.61062096470055E-6,,,,,,,,,,,,,,,,,,,,,299.580627441406,299.5888671875,-339.986511230469,-339.986511230469,52.5664719895729,5.68065836486865,34.3315773010254,28,1,0,0,1,0.31219482421875,32.7468223571777,1,1,1,299.580627441406,0,299.584747314453,,,,,,,,,,,,,,,,,,,,,,,,,,,,,,,,,
,3765441939.94548,299.618255615234,-360.022155761719,-0.000607764306147564,4.08324968139284E-8,1,2,13.9012460708618,4.99650349616785,4.91000013425946,-0.728688160295614,-0.109835355151274,1,1.65850374824195E-6,,,,,,,,,,,,,,,,,,,,,299.605133056641,299.631378173828,-360.022155761719,-360.022155761719,52.6587041548421,5.68077849694213,34.4186363220215,28,1,0,0,1,0.312728881835937,32.7468223571777,1,1,1,299.631378173828,0,299.618255615234,,,,,,,,,,,,,,,,,,,,,,,,,,,,,,,,,
,3765441965.88717,299.758850097656,-380.057800292969,-0.000607750282652911,3.65428754048767E-8,1,2,13.9012460708618,4.99640259045106,4.91000013425946,-0.728649332525936,-0.109837847520803,1,1.65165977567969E-6,,,,,,,,,,,,,,,,,,,,,299.758728027344,299.758972167969,-380.057800292969,-380.057800292969,52.6094615581306,5.68152004028275,34.5181350708008,28,1,0,0,1,0.311050415039063,32.7468223571777,1,1,1,299.758972167969,0,299.758850097656,,,,,,,,,,,,,,,,,,,,,,,,,,,,,,,,,
,3765441991.44617,299.7177734375,-399.947692871094,-0.000607696681653152,6.52703288053029E-8,1,2,13.9012460708618,4.99647566407932,4.91000013425946,-0.728552986850338,-0.110137325903494,1,1.39543462205244E-6,,,,,,,,,,,,,,,,,,,,,299.700988769531,299.734558105469,-399.947692871094,-399.947692871094,52.6676928828133,5.68127113762894,34.630069732666,28,1,0,0,1,0.310745239257812,32.7468223571777,1,1,1,299.700988769531,0,299.7177734375,,,,,,,,,,,,,,,,,,,,,,,,,,,,,,,,,
,3765442016.79206,299.639099121094,-380.069915771484,-0.00060793935383451,4.89780876923018E-8,1,2,13.9012460708618,4.99661278133074,4.91000013425946,-0.728901648276807,-0.109993364857426,1,1.55636591622202E-6,,,,,,,,,,,,,,,,,,,,,299.629455566406,299.648742675781,-380.069915771484,-380.069915771484,52.6426807701979,5.68111334528807,34.7171287536621,28,1,0,0,1,0.310516357421875,32.7468223571777,1,1,1,299.648742675781,0,299.639099121094,,,,,,,,,,,,,,,,,,,,,,,,,,,,,,,,,
,3765442039.28059,299.705154418945,-360.1435546875,-0.00060811046677733,4.90878549622552E-8,1,2,13.9012460708618,4.99640175549654,4.91000013425946,-0.729083491052572,-0.109886663528776,1,1.66620110027984E-6,,,,,,,,,,,,,,,,,,,,,299.7021484375,299.708160400391,-360.1435546875,-360.1435546875,52.5950014305248,5.68142379861998,34.7917518615723,28,1,0,0,1,0.311737060546875,32.7468223571777,1,1,1,299.708160400391,0,299.705154418945,,,,,,,,,,,,,,,,,,,,,,,,,,,,,,,,,
,3765442063.84507,299.660354614258,-340.120086669922,-0.000608294529597917,8.67465435702345E-8,1,2,13.9012460708618,4.99643671299053,4.91000013425946,-0.729301175657047,-0.109987406644397,1,1.6113021042458E-6,,,,,,,,,,,,,,,,,,,,,299.650207519531,299.670501708984,-340.120086669922,-340.120086669922,52.6696469541113,5.6818077230212,34.9285583496094,28,1,0,0,1,0.313186645507812,32.7468223571777,1,1,1,299.650207519531,0,299.660354614258,,,,,,,,,,,,,,,,,,,,,,,,,,,,,,,,,
,3765442110.98104,299.536239624023,-320.011596679687,-0.000608472260195957,5.20363113838637E-8,1,2,13.9012460708618,4.99647315834845,4.91000013425946,-0.729515990138403,-0.110058319675546,1,1.58036170033255E-6,,,,,,,,,,,,,,,,,,,,,299.532501220703,299.539978027344,-320.011596679687,-320.011596679687,52.7458557347364,5.6812032480417,34.8788108825684,28,1,0,0,1,0.3118896484375,32.7468223571777,1,1,1,299.539978027344,0,299.536239624023,,,,,,,,,,,,,,,,,,,,,,,,,,,,,,,,,
,3765442136.53753,299.650085449219,-299.95166015625,-0.000608481133500946,7.05602834369158E-8,1,2,13.9012460708618,4.99656514350378,4.91000013425946,-0.729530378229994,-0.110161786017782,1,1.49777814752889E-6,,,,,,,,,,,,,,,,,,,,,299.649810791016,299.650360107422,-299.95166015625,-299.95166015625,52.6774632393037,5.68120100070442,34.8912467956543,28,1,0,0,1,0.31158447265625,32.7468223571777,1,1,1,299.649810791016,0,299.650085449219,,,,,,,,,,,,,,,,,,,,,,,,,,,,,,,,,
,3765442159.92265,299.706497192383,-280.110321044922,-0.00060861125369404,5.33228097240708E-8,1,2,13.9012460708618,4.99647928713797,4.91000013425946,-0.729679802257057,-0.110110319457608,1,1.55847020124288E-6,,,,,,,,,,,,,,,,,,,,,299.702484130859,299.710510253906,-280.110321044922,-280.110321044922,52.8349613859287,5.68168874532879,34.9285583496094,28,1,0,0,1,0.311660766601562,32.7468223571777,1,1,1,299.710510253906,0,299.706497192383,,,,,,,,,,,,,,,,,,,,,,,,,,,,,,,,,
,3765442182.78873,299.735931396484,-260.038269042969,-0.000608676546300864,5.47302583895993E-8,1,2,13.9012460708618,4.99652329748854,4.91000013425946,-0.729759692114007,-0.110172093374871,1,1.51809183864918E-6,,,,,,,,,,,,,,,,,,,,,299.732604980469,299.7392578125,-260.038269042969,-260.038269042969,52.6938774382075,5.68134867677637,35.0156173706055,28,1,0,0,1,0.314483642578125,32.7468223571777,1,1,1,299.7392578125,0,299.735931396484,,,,,,,,,,,,,,,,,,,,,,,,,,,,,,,,,
,3765442205.79762,299.736907958984,-240.002624511719,-0.000608737550602608,7.79430652579055E-8,1,2,13.9012460708618,4.99653175873807,4.91000013425946,-0.729847079006502,-0.11010195507045,1,1.58620006853177E-6,,,,,,,,,,,,,,,,,,,,,299.728454589844,299.745361328125,-240.002624511719,-240.002624511719,52.6712102111498,5.68132975147999,35.0778045654297,28,1,0,0,1,0.312881469726562,32.7468223571777,1,1,1,299.728454589844,0,299.736907958984,,,,,,,,,,,,,,,,,,,,,,,,,,,,,,,,,
,3765442226.78336,299.8193359375,-220.027694702148,-0.000608771434571505,7.55578169052652E-8,1,2,13.9012460708618,4.99650173295696,4.91000013425946,-0.729883447910176,-0.110094566564168,1,1.5967881050915E-6,,,,,,,,,,,,,,,,,,,,,299.810821533203,299.827850341797,-220.027694702148,-220.027694702148,52.7880636747748,5.68167996579876,35.1399879455566,28,1,0,0,1,0.311203002929687,32.7468223571777,1,1,1,299.827850341797,0,299.8193359375,,,,,,,,,,,,,,,,,,,,,,,,,,,,,,,,,
,3765442247.7048,299.889709472656,-200.162063598633,-0.000608846122950412,4.80586816125394E-8,1,2,13.9012460708618,4.9965381184392,4.91000013425946,-0.729986065389545,-0.110072921197968,1,1.62725900269046E-6,,,,,,,,,,,,,,,,,,,,,299.88330078125,299.896118164063,-200.162063598633,-200.162063598633,52.6805897533806,5.68128952679533,35.22705078125,28,1,0,0,1,0.311660766601562,32.7468223571777,1,1,1,299.896118164063,0,299.889709472656,,,,,,,,,,,,,,,,,,,,,,,,,,,,,,,,,
,3765442270.28423,299.928527832031,-180.053573608398,-0.000608784814491104,3.9310264721226E-8,1,2,13.9012460708618,4.9966812671941,4.91000013425946,-0.729939374507607,-0.110083789591846,1,1.61249082922888E-6,,,,,,,,,,,,,,,,,,,,,299.920135498047,299.936920166016,-180.053573608398,-180.053573608398,52.7802473895825,5.68061178176906,35.3016700744629,28,1,0,0,1,0.312118530273438,32.7468223571777,1,1,1,299.920135498047,0,299.928527832031,,,,,,,,,,,,,,,,,,,,,,,,,,,,,,,,,
,3765442290.78484,299.96501159668,-160.05436706543,-0.000608711589314605,6.58677313395567E-8,1,2,13.9012460708618,4.99661371366999,4.91000013425946,-0.729820443786871,-0.110180562528024,1,1.51875215099609E-6,,,,,,,,,,,,,,,,,,,,,299.963928222656,299.966094970703,-160.05436706543,-160.05436706543,52.697394766544,5.6808893971813,35.376293182373,28,1,0,0,1,0.31097412109375,32.7468223571777,1,1,1,299.963928222656,0,299.96501159668,,,,,,,,,,,,,,,,,,,,,,,,,,,,,,,,,
,3765442314.71164,299.815444946289,-140.213012695312,-0.000608669564893222,4.30686809582417E-8,1,2,13.9012460708618,4.99655520667622,4.91000013425946,-0.729761462825284,-0.110148595882141,1,1.53745437524341E-6,,,,,,,,,,,,,,,,,,,,,299.800262451172,299.830627441406,-140.213012695312,-140.213012695312,52.659876597621,5.68099460055643,35.4882278442383,28,1,0,0,1,0.31219482421875,32.7468223571777,1,1,1,299.800262451172,0,299.815444946289,,,,,,,,,,,,,,,,,,,,,,,,,,,,,,,,,
,3765442339.5705,299.721801757812,-120.104522705078,-0.000608569699959233,4.14102030731218E-8,1,2,13.9012460708618,4.99689962450467,4.91000013425946,-0.729711571317924,-0.110148504640123,1,1.53113603852174E-6,,,,,,,,,,,,,,,,,,,,,299.719360351562,299.724243164063,-120.104522705078,-120.104522705078,52.6098523723902,5.68048361020077,35.5504150390625,28,1,0,0,1,0.311355590820313,32.7468223571777,1,1,1,299.724243164063,0,299.721801757812,,,,,,,,,,,,,,,,,,,,,,,,,,,,,,,,,
,3765442364.63414,299.904678344727,-100.008171081543,-0.000608383385364352,4.10713879392469E-8,1,2,13.9012460708618,4.99659356059079,4.91000013425946,-0.729440530082464,-0.11000497433881,1,1.61434983128085E-6,,,,,,,,,,,,,,,,,,,,,299.891448974609,299.917907714844,-100.008171081543,-100.008171081543,52.6782448678229,5.68121769411755,35.6374740600586,28,1,0,0,1,0.310897827148438,32.7468223571777,1,1,1,299.917907714844,0,299.904678344727,,,,,,,,,,,,,,,,,,,,,,,,,,,,,,,,,
,3765442386.16631,300.17366027832,-79.972541809082,-0.000607982052447358,2.52453749983592E-8,1,2,13.9012460708618,4.99675177866306,4.91000013425946,-0.72895989585156,-0.110145815874385,1,1.43932633351157E-6,,,,,,,,,,,,,,,,,,,,,300.159790039063,300.187530517578,-79.972541809082,-79.972541809082,52.731004792871,5.68017797943796,35.7245330810547,28,1,0,0,1,0.311508178710937,32.7468223571777,1,1,1,300.187530517578,0,300.17366027832,,,,,,,,,,,,,,,,,,,,,,,,,,,,,,,,,
,3765442405.73241,300.278060913086,-60.0704803466797,-0.000607551392037134,5.76655165277796E-8,1,2,13.9012460708618,4.99682887037509,4.91000013425946,-0.728459480057062,-0.110069649270347,1,1.43875836486971E-6,,,,,,,,,,,,,,,,,,,,,300.273590087891,300.282531738281,-60.0704803466797,-60.0704803466797,52.7009120948806,5.68000557727418,35.7867202758789,28,1,0,0,1,0.3125,32.7468223571777,1,1,1,300.273590087891,0,300.278060913086,,,,,,,,,,,,,,,,,,,,,,,,,,,,,,,,,
,3765442426.14786,300.240264892578,-40.0348434448242,-0.00060700203465182,6.57458493819298E-8,1,2,13.9012460708618,4.99662129628116,4.91000013425946,-0.727796539697572,-0.109713567829402,1,1.64614266323063E-6,,,,,,,,,,,,,,,,,,,,,300.234069824219,300.246459960937,-40.0348434448242,-40.0348434448242,52.6813713818998,5.68082442576128,35.8613395690918,28,1,0,0,1,0.311737060546875,32.7468223571777,1,1,1,300.247253417969,0,300.240264892578,,,,,,,,,,,,,,,,,,,,,,,,,,,,,,,,,
,3765442451.99014,300.274688720703,-19.9384937286377,-0.000606015674959496,4.92728632219289E-8,1,2,13.9012460708618,4.99642321347175,4.91000013425946,-0.726543395547896,-0.109723640984741,1,1.48118893741668E-6,,,,,,,,,,,,,,,,,,,,,300.266448974609,300.282928466797,-19.9384937286377,-19.9384937286377,52.6934866239479,5.68102496794135,35.9608383178711,28,1,0,0,1,0.31158447265625,32.7468223571777,1,1,1,300.266448974609,0,300.274688720703,,,,,,,,,,,,,,,,,,,,,,,,,,,,,,,,,
,3765442472.46454,300.16423034668,0.109285280108452,-0.00060440816838667,6.32905114272882E-8,1,2,13.9012460708618,4.99641812694235,4.91000013425946,-0.724618399373534,-0.109411192185856,1,1.49498359669664E-6,,,,,,,,,,,,,,,,,,,,,300.160064697266,300.168395996094,0.109285280108452,0.109285280108452,52.6915325526498,5.68071480470054,36.0230255126953,28,1,0,0,1,0.311431884765625,32.7468223571777,1,1,1,300.168395996094,0,300.16423034668,,,,,,,,,,,,,,,,,,,,,,,,,,,,,,,,,
,3765442493.29744,300.28630065918,19.9870643615723,-0.000588999844199592,9.34666929474991E-8,1,2,13.9012460708618,4.99648072380336,4.91000013425946,-0.706188898746649,-0.106422619881439,1,1.62476346253617E-6,,,,,,,,,,,,,,,,,,,,,300.284301757812,300.288299560547,19.9870643615723,19.9870643615723,52.6704285826306,5.68086011003971,36.0852088928223,28,1,0,0,1,0.312423706054687,32.7468223571777,1,1,1,300.288299560547,0,300.28630065918,,,,,,,,,,,,,,,,,,,,,,,,,,,,,,,,,
,3765442514.25894,300.230712890625,40.0348434448242,0.000539425573257628,1.05436542703097E-7,1,2,13.9012460708618,4.99647517644216,4.91000013425946,0.646750148485834,0.0974654093641273,1,-1.48784488326237E-6,,,,,,,,,,,,,,,,,,,,,300.221862792969,300.239562988281,40.0348434448242,40.0348434448242,52.7286599073133,5.6807730231061,36.1722679138184,28,1,0,0,1,0.312347412109375,32.7468223571777,1,1,1,300.221862792969,0,300.230712890625,,,,,,,,,,,,,,,,,,,,,,,,,,,,,,,,,
,3765442539.43978,300.06689453125,59.8761940002441,0.000590273076700685,5.34610174819311E-8,1,2,13.9012460708618,4.99642237214217,4.91000013425946,0.707706982761678,0.106630158205386,1,-1.64559544999257E-6,,,,,,,,,,,,,,,,,,,,,300.066864013672,300.066925048828,59.8761940002441,59.8761940002441,52.7388210780633,5.68120417351644,36.2220191955566,28,1,0,0,1,0.312957763671875,32.7468223571777,1,1,1,300.066925048828,0,300.06689453125,,,,,,,,,,,,,,,,,,,,,,,,,,,,,,,,,
,3765442561.9738,299.949920654297,79.972541809082,0.000594328870543108,7.56335108839542E-8,1,2,13.9012460708618,4.99637811036856,4.91000013425946,0.71253821158138,0.107508379199014,1,-1.53432266351608E-6,,,,,,,,,,,,,,,,,,,,,299.937774658203,299.962066650391,79.972541809082,79.972541809082,52.6829346389383,5.68112862366322,36.1847076416016,28,1,0,0,1,0.313262939453125,32.7468223571777,1,1,1,299.937774658203,0,299.949920654297,,,,,,,,,,,,,,,,,,,,,,,,,,,,,,,,,
,3765442583.16667,299.854019165039,99.9717483520508,0.00059703008621619,5.45123823098662E-8,1,2,13.9012460708618,4.99640653936432,4.91000013425946,0.715769302717652,0.108083397475518,1,-1.46992998864295E-6,,,,,,,,,,,,,,,,,,,,,299.851837158203,299.856201171875,99.9717483520508,99.9717483520508,52.6555776407652,5.68081525686414,36.1598320007324,28,1,0,0,1,0.31341552734375,32.7468223571777,1,1,1,299.856201171875,0,299.854019165039,,,,,,,,,,,,,,,,,,,,,,,,,,,,,,,,,
,3765442605.9017,299.815338134766,119.91024017334,0.000599440799938482,5.62709936954584E-8,1,2,13.9012460708618,4.99667845599633,4.91000013425946,0.718733818913972,0.108403276328173,1,-1.58005814295988E-6,,,,,,,,,,,,,,,,,,,,,299.815307617188,299.815368652344,119.91024017334,119.91024017334,52.544977205294,5.68028770625607,36.1971435546875,28,1,0,0,1,0.312652587890625,32.7468223571777,1,1,1,299.815307617188,0,299.815338134766,,,,,,,,,,,,,,,,,,,,,,,,,,,,,,,,,
,3765442630.67012,299.930770874023,139.945877075195,0.000601250405253673,3.18526584608347E-8,1,2,13.9012460708618,4.99657282152839,4.91000013425946,0.720864210097235,0.10884346739631,1,-1.48788591664884E-6,,,,,,,,,,,,,,,,,,,,,299.923492431641,299.938049316406,139.945877075195,139.945877075195,52.6829346389383,5.68092608326914,36.2717666625977,28,1,0,0,1,0.310211181640625,32.7468223571777,1,1,1,299.938049316406,0,299.930770874023,,,,,,,,,,,,,,,,,,,,,,,,,,,,,,,,,
,3765442654.09148,299.969055175781,160.005798339844,0.000602705244652228,6.28257509122628E-8,1,2,13.9012460708618,4.99643224262238,4.91000013425946,0.722569628917817,0.109168717814082,1,-1.43623597721728E-6,,,,,,,,,,,,,,,,,,,,,299.962860107422,299.975250244141,160.005798339844,160.005798339844,52.6841070817171,5.6812372171331,36.3339500427246,28,1,0,0,1,0.311508178710937,32.7468223571777,1,1,1,299.962860107422,0,299.969055175781,,,,,,,,,,,,,,,,,,,,,,,,,,,,,,,,,
,3765442679.72118,299.847717285156,180.017150878906,0.000603960744944438,5.11333076709806E-8,1,2,13.9012460708618,4.996405779176,4.91000013425946,0.724092859764719,0.1092425584796,1,-1.56668801069075E-6,,,,,,,,,,,,,,,,,,,,,299.839141845703,299.856292724609,180.017150878906,180.017150878906,52.6055534155344,5.68083810430554,36.421012878418,28,1,0,0,1,0.312042236328125,32.7468223571777,1,1,1,299.839141845703,0,299.847717285156,,,,,,,,,,,,,,,,,,,,,,,,,,,,,,,,,
,3765442703.45105,299.733764648438,199.931350708008,0.000604847194700014,6.8362462877929E-8,1,2,13.9012460708618,4.99632187135784,4.91000013425946,0.725146866115028,0.109345477036315,1,-1.61473804909969E-6,,,,,,,,,,,,,,,,,,,,,299.728881835937,299.738647460937,199.931350708008,199.931350708008,52.717717108044,5.68171619606294,36.4956398010254,28,1,0,0,1,0.312423706054687,32.7468223571777,1,1,1,299.738647460937,0,299.733764648438,,,,,,,,,,,,,,,,,,,,,,,,,,,,,,,,,
,3765442726.41614,299.722763061523,219.979141235352,0.000605487378746524,6.15316785817555E-8,1,2,13.9012460708618,4.99651049264776,4.91000013425946,0.72592115188156,0.109674772640693,1,-1.44311586797313E-6,,,,,,,,,,,,,,,,,,,,,299.721527099609,299.723999023438,219.979141235352,219.979141235352,52.6907509241306,5.68075643531202,36.5826988220215,28,1,0,0,1,0.3118896484375,32.7468223571777,1,1,1,299.723999023438,0,299.722763061523,,,,,,,,,,,,,,,,,,,,,,,,,,,,,,,,,
,3765442749.39289,299.770812988281,239.954040527344,0.000606092744329855,4.96601980760329E-8,1,2,13.9012460708618,4.99658079880631,4.91000013425946,0.72669870836827,0.10954327978509,1,-1.64758517541389E-6,,,,,,,,,,,,,,,,,,,,,299.769348144531,299.772277832031,239.954040527344,239.954040527344,52.6485429840921,5.68046468658871,36.6448822021484,28,1,0,0,1,0.312881469726562,32.7468223571777,1,1,1,299.772277832031,0,299.770812988281,,,,,,,,,,,,,,,,,,,,,,,,,,,,,,,,,
,3765442772.55978,299.804489135742,260.062530517578,0.000606535615948642,6.61952310924385E-8,1,2,13.9012460708618,4.99646317527607,4.91000013425946,0.727202031817019,0.109642621684372,1,-1.62964803281807E-6,,,,,,,,,,,,,,,,,,,,,299.801330566406,299.807647705078,260.062530517578,260.062530517578,52.656750083544,5.68110198889236,36.7319450378418,28,1,0,0,1,0.310897827148438,32.7468223571777,1,1,1,299.801330566406,0,299.804489135742,,,,,,,,,,,,,,,,,,,,,,,,,,,,,,,,,
,3765442793.57522,299.857681274414,279.928192138672,0.000606809160695056,4.7952947364847E-8,1,2,13.9012460708618,4.99619445658152,4.91000013425946,0.72747602617002,0.109675703532436,1,-1.63709468006069E-6,,,,,,,,,,,,,,,,,,,,,299.855499267578,299.85986328125,279.928192138672,279.928192138672,52.702475351919,5.68188767284679,36.8065643310547,28,1,0,0,1,0.312728881835937,32.7468223571777,1,1,1,299.85986328125,0,299.857681274414,,,,,,,,,,,,,,,,,,,,,,,,,,,,,,,,,
,3765442817.76132,299.857574462891,300.012390136719,0.000607056827267764,5.44792963301803E-8,1,2,13.9012460708618,4.99624756140999,4.91000013425946,0.727777574796231,0.109763031705235,1,-1.60361746123114E-6,,,,,,,,,,,,,,,,,,,,,299.854919433594,299.860229492188,300.012390136719,300.012390136719,52.5899208451498,5.68082832022654,36.906063079834,28,1,0,0,1,0.310821533203125,32.7468223571777,1,1,1,299.8544921875,0,299.857574462891,,,,,,,,,,,,,,,,,,,,,,,,,,,,,,,,,
,3765442839.18394,299.84162902832,320.035888671875,0.000607252186510671,7.18530055140962E-8,1,2,13.9012460708618,4.99621530833094,4.91000013425946,0.728013869876528,0.109740574064478,1,-1.65151542554151E-6,,,,,,,,,,,,,,,,,,,,,299.841583251953,299.841674804687,320.035888671875,320.035888671875,52.8310532433325,5.68191608664539,36.955810546875,28,1,0,0,1,0.31158447265625,32.7468223571777,1,1,1,299.841583251953,0,299.84162902832,,,,,,,,,,,,,,,,,,,,,,,,,,,,,,,,,
,3765442864.26528,299.845245361328,339.937957763672,0.000607279477886815,3.58485493364481E-8,1,2,13.9012460708618,4.99620003069823,4.91000013425946,0.728013614993102,0.109939352791023,1,-1.48943456469051E-6,,,,,,,,,,,,,,,,,,,,,299.836273193359,299.854217529297,339.937957763672,339.937957763672,52.7423384063998,5.68137024963013,37.0428695678711,28,1,0,0,1,0.310592651367188,32.7468223571777,1,1,1,299.8349609375,0,299.845245361328,,,,,,,,,,,,,,,,,,,,,,,,,,,,,,,,,
,3765442887.34386,299.823669433594,359.997863769531,0.000607497001006665,6.48193226472503E-8,1,2,13.9012460708618,4.99619008123498,4.91000013425946,0.728291118085603,0.109856094737921,1,-1.59204827711546E-6,,,,,,,,,,,,,,,,,,,,,299.820526123047,299.826812744141,359.997863769531,359.997863769531,52.6290022711113,5.68171475419575,37.1423683166504,28,1,0,0,1,0.314254760742188,32.7468223571777,1,1,1,299.820526123047,0,299.823669433594,,,,,,,,,,,,,,,,,,,,,,,,,,,,,,,,,
,3765442913.03736,299.760208129883,379.9970703125,0.000607683817960489,3.66041016340346E-8,1,2,13.9012460708618,4.99603073059703,4.91000013425946,0.728496544138546,0.109792131862856,1,-1.66998113685087E-6,,,,,,,,,,,,,,,,,,,,,299.749755859375,299.770660400391,379.9970703125,379.9970703125,52.7306139786114,5.68245814233139,37.2418632507324,28,1,0,0,1,0.311050415039063,32.7468223571777,1,1,1,299.749755859375,0,299.760208129883,,,,,,,,,,,,,,,,,,,,,,,,,,,,,,,,,
,3765442936.52305,299.675552368164,400.032684326172,0.000607598078798991,3.47356906659416E-8,1,2,13.9012460708618,4.99597805661866,4.91000013425946,0.728366225637469,0.109883773149112,1,-1.57897820799993E-6,,,,,,,,,,,,,,,,,,,,,299.674438476562,299.676666259766,400.032684326172,400.032684326172,52.7056018659959,5.68284901516183,37.2169914245605,28,1,0,0,1,0.3125,32.7468223571777,1,1,1,299.676666259766,0,299.675552368164,,,,,,,,,,,,,,,,,,,,,,,,,,,,,,,,,